2019-12-11 20:26:41,947 ERROR: Exception on /user/tcarsello [GET] [in /home/tom/.local/lib/python3.6/site-packages/flask/app.py:1891]
Traceback (most recent call last):
  File "/home/tom/.local/lib/python3.6/site-packages/sqlalchemy/engine/base.py", line 1246, in _execute_context
    cursor, statement, parameters, context
  File "/home/tom/.local/lib/python3.6/site-packages/sqlalchemy/engine/default.py", line 581, in do_execute
    cursor.execute(statement, parameters)
sqlite3.OperationalError: no such table: followers

The above exception was the direct cause of the following exception:

Traceback (most recent call last):
  File "/home/tom/.local/lib/python3.6/site-packages/flask/app.py", line 2446, in wsgi_app
    response = self.full_dispatch_request()
  File "/home/tom/.local/lib/python3.6/site-packages/flask/app.py", line 1951, in full_dispatch_request
    rv = self.handle_user_exception(e)
  File "/home/tom/.local/lib/python3.6/site-packages/flask/app.py", line 1820, in handle_user_exception
    reraise(exc_type, exc_value, tb)
  File "/home/tom/.local/lib/python3.6/site-packages/flask/_compat.py", line 39, in reraise
    raise value
  File "/home/tom/.local/lib/python3.6/site-packages/flask/app.py", line 1949, in full_dispatch_request
    rv = self.dispatch_request()
  File "/home/tom/.local/lib/python3.6/site-packages/flask/app.py", line 1935, in dispatch_request
    return self.view_functions[rule.endpoint](**req.view_args)
  File "/home/tom/.local/lib/python3.6/site-packages/flask_login/utils.py", line 261, in decorated_view
    return func(*args, **kwargs)
  File "/home/tom/Desktop/nnhsse-tcarsello-miniunit/app/routes.py", line 71, in user
    return render_template('user.html', user=user, posts=posts)
  File "/home/tom/.local/lib/python3.6/site-packages/flask/templating.py", line 140, in render_template
    ctx.app,
  File "/home/tom/.local/lib/python3.6/site-packages/flask/templating.py", line 120, in _render
    rv = template.render(context)
  File "/home/tom/.local/lib/python3.6/site-packages/jinja2/asyncsupport.py", line 76, in render
    return original_render(self, *args, **kwargs)
  File "/home/tom/.local/lib/python3.6/site-packages/jinja2/environment.py", line 1008, in render
    return self.environment.handle_exception(exc_info, True)
  File "/home/tom/.local/lib/python3.6/site-packages/jinja2/environment.py", line 780, in handle_exception
    reraise(exc_type, exc_value, tb)
  File "/home/tom/.local/lib/python3.6/site-packages/jinja2/_compat.py", line 37, in reraise
    raise value.with_traceback(tb)
  File "/home/tom/Desktop/nnhsse-tcarsello-miniunit/app/templates/user.html", line 1, in top-level template code
    {% extends "base.html" %}
  File "/home/tom/Desktop/nnhsse-tcarsello-miniunit/app/templates/base.html", line 31, in top-level template code
    {% block content %}{% endblock %}
  File "/home/tom/Desktop/nnhsse-tcarsello-miniunit/app/templates/user.html", line 13, in block "content"
    <p>{{ user.followers.count() }} followers, {{ user.followed.count() }} following.</p>
  File "/home/tom/.local/lib/python3.6/site-packages/sqlalchemy/orm/dynamic.py", line 335, in count
    return self._clone(sess).count()
  File "/home/tom/.local/lib/python3.6/site-packages/sqlalchemy/orm/query.py", line 3630, in count
    return self.from_self(col).scalar()
  File "/home/tom/.local/lib/python3.6/site-packages/sqlalchemy/orm/query.py", line 3355, in scalar
    ret = self.one()
  File "/home/tom/.local/lib/python3.6/site-packages/sqlalchemy/orm/query.py", line 3325, in one
    ret = self.one_or_none()
  File "/home/tom/.local/lib/python3.6/site-packages/sqlalchemy/orm/query.py", line 3294, in one_or_none
    ret = list(self)
  File "/home/tom/.local/lib/python3.6/site-packages/sqlalchemy/orm/query.py", line 3367, in __iter__
    return self._execute_and_instances(context)
  File "/home/tom/.local/lib/python3.6/site-packages/sqlalchemy/orm/query.py", line 3392, in _execute_and_instances
    result = conn.execute(querycontext.statement, self._params)
  File "/home/tom/.local/lib/python3.6/site-packages/sqlalchemy/engine/base.py", line 982, in execute
    return meth(self, multiparams, params)
  File "/home/tom/.local/lib/python3.6/site-packages/sqlalchemy/sql/elements.py", line 287, in _execute_on_connection
    return connection._execute_clauseelement(self, multiparams, params)
  File "/home/tom/.local/lib/python3.6/site-packages/sqlalchemy/engine/base.py", line 1101, in _execute_clauseelement
    distilled_params,
  File "/home/tom/.local/lib/python3.6/site-packages/sqlalchemy/engine/base.py", line 1250, in _execute_context
    e, statement, parameters, cursor, context
  File "/home/tom/.local/lib/python3.6/site-packages/sqlalchemy/engine/base.py", line 1476, in _handle_dbapi_exception
    util.raise_from_cause(sqlalchemy_exception, exc_info)
  File "/home/tom/.local/lib/python3.6/site-packages/sqlalchemy/util/compat.py", line 398, in raise_from_cause
    reraise(type(exception), exception, tb=exc_tb, cause=cause)
  File "/home/tom/.local/lib/python3.6/site-packages/sqlalchemy/util/compat.py", line 152, in reraise
    raise value.with_traceback(tb)
  File "/home/tom/.local/lib/python3.6/site-packages/sqlalchemy/engine/base.py", line 1246, in _execute_context
    cursor, statement, parameters, context
  File "/home/tom/.local/lib/python3.6/site-packages/sqlalchemy/engine/default.py", line 581, in do_execute
    cursor.execute(statement, parameters)
sqlalchemy.exc.OperationalError: (sqlite3.OperationalError) no such table: followers
[SQL: SELECT count(*) AS count_1 
FROM (SELECT user.id AS user_id, user.username AS user_username, user.email AS user_email, user.password_hash AS user_password_hash, user.about_me AS user_about_me, user.last_seen AS user_last_seen 
FROM user, followers 
WHERE followers.followed_id = ? AND followers.follower_id = user.id) AS anon_1]
[parameters: (3,)]
(Background on this error at: http://sqlalche.me/e/e3q8)
2019-12-11 20:26:56,879 INFO: Microblog startup [in /home/tom/Desktop/nnhsse-tcarsello-miniunit/app/__init__.py:31]
2019-12-11 20:27:32,018 INFO: Microblog startup [in /home/tom/Desktop/nnhsse-tcarsello-miniunit/app/__init__.py:31]
2019-12-11 20:27:35,216 INFO: Microblog startup [in /home/tom/Desktop/nnhsse-tcarsello-miniunit/app/__init__.py:31]
2019-12-11 20:27:39,038 INFO: Microblog startup [in /home/tom/Desktop/nnhsse-tcarsello-miniunit/app/__init__.py:31]
2019-12-11 20:27:53,949 INFO: Microblog startup [in /home/tom/Desktop/nnhsse-tcarsello-miniunit/app/__init__.py:31]
2019-12-11 20:28:17,263 INFO: Microblog startup [in /home/tom/Desktop/nnhsse-tcarsello-miniunit/app/__init__.py:31]
2019-12-11 20:35:34,514 INFO: Microblog startup [in /home/tom/Desktop/nnhsse-tcarsello-miniunit/app/__init__.py:31]
2019-12-11 20:38:17,340 INFO: Microblog startup [in /home/tom/Desktop/nnhsse-tcarsello-miniunit/app/__init__.py:31]
2019-12-11 20:39:17,614 INFO: Microblog startup [in /home/tom/Desktop/nnhsse-tcarsello-miniunit/app/__init__.py:31]
2019-12-11 20:39:20,664 INFO: Microblog startup [in /home/tom/Desktop/nnhsse-tcarsello-miniunit/app/__init__.py:31]
2019-12-11 20:44:12,424 INFO: Microblog startup [in /home/tom/Desktop/nnhsse-tcarsello-miniunit/app/__init__.py:31]
2019-12-11 20:45:41,124 INFO: Microblog startup [in /home/tom/Desktop/nnhsse-tcarsello-miniunit/app/__init__.py:31]
2019-12-11 20:46:02,409 INFO: Microblog startup [in /home/tom/Desktop/nnhsse-tcarsello-miniunit/app/__init__.py:31]
2019-12-11 20:48:16,459 INFO: Microblog startup [in /home/tom/Desktop/nnhsse-tcarsello-miniunit/app/__init__.py:31]
2019-12-11 20:50:16,929 INFO: Microblog startup [in /home/tom/Desktop/nnhsse-tcarsello-miniunit/app/__init__.py:31]
